<?xml version="1.0" ?>
<robot xmlns:xacro="http://www.ros.org/wiki/xacro">

<xacro:property name="connect_offset" value="0.02633" />
<xacro:property name="thigh_offset_y" value="-0.0645" />
<xacro:property name="thigh_offset_z" value="-0.0145" />



<xacro:macro name="phantomx" params="parent *origin">


    <joint name="j_phantomx_attachment" type="fixed">
      <parent link="${parent}"/>
      <child link="MP_BODY"/>
      <xacro:insert_block name="origin" />
    </joint>
    

    <link name="MP_BODY">
      <inertial>
        <origin xyz="0 0 0" />
        <mass value="0.97559947"/>
        <inertia ixx="3.1081800"  ixy="-0.25460189"  ixz="2.0318174" iyy="6.3787776" iyz="0.16417863" izz="5.3316425" />
      </inertial>
      <visual>
        <!--origin xyz="-0.0235 0 -0.03525" rpy="0 0 0" /-->
        <origin xyz="0 0 0" rpy="0 0 0" />
        <geometry>
          <!--box size="0.102 0.109 0.106" /-->
          <mesh filename="package://phantomx_description/meshes/body.STL"  scale="1 1 1"/>
        </geometry>
        <material name="Grey">
          <color rgba="0.20 0.20 0.20 1.0"/>
        </material>
      </visual>
      <collision>
        <origin xyz="0 0 0" rpy="0 0 0" />
        <geometry>
          <mesh filename="package://phantomx_description/meshes/body_coll.STL"  scale="1 1 1"/>
        </geometry>
      </collision>
    </link>

    <gazebo reference="MP_BODY">    
      <material>Gazebo/Grey</material>
    </gazebo>

	  <link name="hokuyo_link">
      <collision>
        <origin xyz="0 0 0" rpy="0 0 0"/>
        <geometry>
          <box size="0.15 0.15 0.15"/>
        </geometry>
      </collision>
      <visual>
        <origin xyz="0 0 0" rpy="0 0 0"/>
        <geometry>
          <mesh filename="package://phantomx_description/meshes/hokuyo.dae"/>
        </geometry>
      </visual>
      <inertial>
        <mass value="0.01" />
        <inertia ixx="0.0051411124"  ixy="-0.00057530255"  ixz="-0.000024729049" iyy="0.0081915737" iyz="-0.000019223094" izz="0.0011379812" />
        <origin xyz="0 0 0" rpy="0 0 0"/>
        <inertia ixx="1e-6" ixy="0" ixz="0" iyy="1e-6" iyz="0" izz="1e-6" />
      </inertial>
    </link>

  <xacro:property name="hokuyo_link" value="0.15" />

  <joint name="hokuyo_joint" type="revolute">
    <axis  xyz="0 1 0"/>
    <origin xyz="0.1 0 0.05" rpy="0 0 0"/>
    <parent link="MP_BODY"/>
    <child link="hokuyo_link"/>
    <limit lower="-0.25" upper="1.0" effort="3" velocity="1"/> 
  </joint>
  
  <!-- hokuyo -->
  <gazebo reference="hokuyo_link">
    <sensor type="ray" name="head_hokuyo_sensor">
      <pose>0 0 0 0 0 0</pose>
      <visualize>true</visualize>
      <update_rate>40</update_rate>
      <ray>
        <scan>
          <horizontal>
            <samples>720</samples>
            <resolution>1</resolution>
            <min_angle>-1.2217</min_angle>
            <max_angle>1.2217</max_angle>
          </horizontal>
        </scan>
        <range>
          <min>0.15</min>
          <max>5.0</max>
          <resolution>0.01</resolution>
        </range>
        <noise>
          <type>gaussian</type>
          <!-- Noise parameters based on published spec for Hokuyo laser
               achieving "+-30mm" accuracy at range < 10m.  A mean of 0.0m and
               stddev of 0.01m will put 99.7% of samples within 0.03m of the true
               reading. -->
          <mean>0.0</mean>
          <stddev>0.01</stddev>
        </noise>
      </ray>
      <!--link the plugin so it references the gazebo library laser library-->
      <plugin name="gazebo_ros_head_hokuyo_controller" filename="libgazebo_ros_laser.so">
        <topicName>/phantomx/LaserScan</topicName>
        <frameName>hokuyo_link</frameName>
      </plugin>
    </sensor>
  </gazebo>
  <gazebo>
    <plugin name="gazebo_ros_control" filename="libgazebo_ros_control.so">
        <robotNamespace>/phantomx</robotNamespace>
      </plugin>
  </gazebo>
  <transmission name="hokuyo_joint">
    <type>transmission_interface/SimpleTransmission</type>
    <actuator name="motor1">
      <mechanicalReduction>1</mechanicalReduction>
    </actuator>
    <joint name="hokuyo_joint">
      <hardwareInterface>EffortJointInterface</hardwareInterface>
    </joint>
  </transmission>

    <xacro:leg_l xyz="0.1248 -0.06164  0.001116"  rpy="0 4.7123 0.7853981633974483" suffix="rf"/>
    <xacro:leg_l xyz="0 -0.1034  0.001116"  rpy="0 4.7123 0" suffix="rm"/>
    <xacro:leg_l xyz="-0.1248 -0.06164  0.001116"  rpy="0 4.7123 -0.7853981633974483" suffix="rr"/>


    <xacro:leg_l xyz="0.1248 0.06164  0.001116"  rpy="0 4.7123 2.356194490192345" suffix="lf"/>
    <xacro:leg_l xyz="0 0.1034  0.001116"  rpy="0 4.7123 3.14159" suffix="lm"/>
    <xacro:leg_l xyz="-0.1248 0.06164  0.001116"  rpy="0 4.7123 3.9269908169872414" suffix="lr"/>

</xacro:macro>





 <xacro:macro name="leg_l" params="xyz rpy suffix">
  <link name="c1_${suffix}">
    <inertial>
      <origin xyz="0 -${connect_offset} 0" rpy="0 0 0"  />
      <mass value="0.024357719"/>
     <inertia ixx="0.0051411124"  ixy="-0.00057530255"  ixz="-0.000024729049" iyy="0.0081915737" iyz="-0.000019223094" izz="0.0011379812" />
    </inertial>
    <visual>
      <origin xyz="0 -0.0252 0" rpy="0 0 0"  />
      <geometry>
        <!--box size="0.045 0.022 0.0325" /-->
        <mesh filename="package://phantomx_description/meshes/connect.STL"  scale="1 1 1"/>
      </geometry>
      <material name="Grey">
        <color rgba="0.20 0.20 0.20 1.0"/>
      </material>
    </visual>
    <collision>
      <origin xyz="0 -${connect_offset} 0" rpy="0 0 0"  />
      <geometry>
        <mesh filename="package://phantomx_description/meshes/connect_coll.STL"  scale="1 1 1"/>
      </geometry>
    </collision>
  </link>


  <link name="c2_${suffix}">
    <inertial>
      <origin xyz="0 -${connect_offset} 0" rpy="0 0 0"  />
      <mass value="0.024357719"/>
     <inertia ixx="0.0051411124"  ixy="-0.00057530255"  ixz="-0.000024729049" iyy="0.0081915737" iyz="-0.000019223094" izz="0.0011379812" />
    </inertial>
    <visual>
      <origin xyz="0 -0.0252 0" rpy="0 0 0"  />
      <geometry>
        <!--box size="0.045 0.022 0.0325" /-->
        <mesh filename="package://phantomx_description/meshes/connect.STL"  scale="1 1 1"/>
      </geometry>
      <material name="Grey">
        <color rgba="0.20 0.20 0.20 1.0"/>
      </material>
    </visual>
    <collision>
      <origin xyz="0 -${connect_offset} 0" rpy="0 0 0"  />
      <geometry>
        <mesh filename="package://phantomx_description/meshes/connect_coll.STL"  scale="1 1 1"/>
      </geometry>
    </collision>
  </link>



  <link name="thigh_${suffix}">
    <inertial>
      <origin xyz="0 0 0" rpy="0 0 0"  />
      <mass value="0.024357719"/>
     <inertia ixx="0.0051411124"  ixy="-0.00057530255"  ixz="-0.000024729049" iyy="0.0081915737" iyz="-0.000019223094" izz="0.0011379812" />
    </inertial>
    <visual>
      <origin xyz="0 0 0" rpy="0 0 0"  />
      <geometry>
        <!--box size="0.045 0.022 0.0325" /-->
        <mesh filename="package://phantomx_description/meshes/thigh_l.STL"  scale="1 1 1"/>
      </geometry>
      <material name="Grey">
        <color rgba="0.20 0.20 0.20 1.0"/>
      </material>
    </visual>
    <collision>
      <origin xyz="0 0 0" rpy="0 0 0"  />
      <geometry>
        <mesh filename="package://phantomx_description/meshes/thigh_l_coll.STL"  scale="1 1 1"/>
      </geometry>
    </collision>
  </link>



  <link name="tibia_${suffix}">
    <inertial>
      <origin xyz="0 0 0" rpy="0 0 0"  />
      <mass value="0.024357719"/>
     <inertia ixx="0.0051411124"  ixy="-0.00057530255"  ixz="-0.000024729049" iyy="0.0081915737" iyz="-0.000019223094" izz="0.0011379812" />
    </inertial>
    <visual>
      <origin xyz="0 0 0" rpy="0 0 0"  />
      <geometry>
        <!--box size="0.045 0.022 0.0325" /-->
        <mesh filename="package://phantomx_description/meshes/tibia_l.STL"  scale="1 1 1"/>
      </geometry>
      <material name="Grey">
        <color rgba="0.20 0.20 0.20 1.0"/>
      </material>
    </visual>
    <collision>
      <origin xyz="0 0 0" rpy="0 0 0"  />
      <geometry>
        <mesh filename="package://phantomx_description/meshes/tibia_l_coll.STL"  scale="1 1 1"/>
      </geometry>
    </collision>
  </link>



  <joint name="j_c1_${suffix}" type="revolute">
    <parent link="MP_BODY"/>
    <child link="c1_${suffix}"/>
    <origin xyz="${xyz}" rpy="${rpy}" />
    <axis xyz="1 0 0" />
    <limit effort="2.8" velocity="5.6548668" lower="-2.6179939" upper="2.6179939" />
  </joint>

  <joint name="j_c2_${suffix}" type="fixed">
    <parent link="c1_${suffix}"/>
    <child link="c2_${suffix}"/>
    <origin xyz="0 -0.054 0" rpy="0 1.5704 3.14159" />
  </joint>


  <joint name="j_thigh_${suffix}" type="revolute">
    <parent link="c2_${suffix}"/>
    <child link="thigh_${suffix}"/>
    <origin xyz="0 0 0" rpy=" 0 3.14159 3.14159" />
    <axis xyz="1 0 0" />
    <limit effort="2.8" velocity="5.6548668" lower="-2.6179939" upper="2.6179939" />
  </joint>

  <joint name="j_tibia_${suffix}" type="revolute">
    <parent link="thigh_${suffix}"/>
    <child link="tibia_${suffix}"/>
    <origin xyz="0 ${thigh_offset_y} ${thigh_offset_z}" rpy="-1.5707 0 3.14159" />
    <axis xyz="1 0 0" />
    <limit effort="2.8" velocity="5.6548668" lower="-2.6179939" upper="2.6179939" />
  </joint>



   <transmission name="t_c1_${suffix}">
    <type>transmission_interface/SimpleTransmission</type>
    <joint name="j_c1_${suffix}">
      <hardwareInterface>EffortJointInterface</hardwareInterface>    
    </joint>
    <actuator name="m_c1_${suffix}">
      <hardwareInterface>EffortJointInterface</hardwareInterface>
      <mechanicalReduction>1</mechanicalReduction>
    </actuator>
  </transmission>


   <transmission name="t_thigh_${suffix}">
    <type>transmission_interface/SimpleTransmission</type>
    <joint name="j_thigh_${suffix}">
      <hardwareInterface>EffortJointInterface</hardwareInterface>    
    </joint>
    <actuator name="m_thigh_${suffix}">
      <hardwareInterface>EffortJointInterface</hardwareInterface>
      <mechanicalReduction>1</mechanicalReduction>
    </actuator>
  </transmission>


   <transmission name="t_tibia_${suffix}">
    <type>transmission_interface/SimpleTransmission</type>
    <joint name="j_tibia_${suffix}">
      <hardwareInterface>EffortJointInterface</hardwareInterface>
    </joint>
    <actuator name="m_tibia_${suffix}">
      <hardwareInterface>EffortJointInterface</hardwareInterface>
      <mechanicalReduction>1</mechanicalReduction>
    </actuator>
  </transmission>



  <gazebo reference="c1_${suffix}">    
    <material>Gazebo/Grey</material>
  </gazebo>

  <gazebo reference="c2_${suffix}">    
    <material>Gazebo/Grey</material>
  </gazebo>

  <gazebo reference="thigh_${suffix}">    
    <material>Gazebo/Grey</material>
  </gazebo>

  <gazebo reference="tibia_${suffix}">    
    <material>Gazebo/Grey</material>
  </gazebo>

  
</xacro:macro>





</robot>
